<?xml version="1.0" ?>
<sdf version='1.6'>
  <world name='default'>
    <light name='sun' type='directional'>
      <cast_shadows>1</cast_shadows>
      <pose frame=''>0 0 10 0 -0 0</pose>
      <diffuse>0.8 0.8 0.8 1</diffuse>
      <specular>0.2 0.2 0.2 1</specular>
      <attenuation>
        <range>1000</range>
        <constant>0.9</constant>
        <linear>0.01</linear>
        <quadratic>0.001</quadratic>
      </attenuation>
      <direction>-0.5 0.1 -0.9</direction>
    </light>
    <model name='ground_plane'>
      <static>1</static>
      <link name='link'>
        <collision name='collision'>
          <geometry>
            <plane>
              <normal>0 0 1</normal>
              <size>100 100</size>
            </plane>
          </geometry>
          <surface>
            <friction>
              <ode>
                <mu>100</mu>
                <mu2>50</mu2>
              </ode>
              <torsional>
                <ode/>
              </torsional>
            </friction>
            <contact>
              <ode/>
            </contact>
            <bounce/>
          </surface>
          <max_contacts>10</max_contacts>
        </collision>
        <visual name='visual'>
          <cast_shadows>0</cast_shadows>
          <geometry>
            <plane>
              <normal>0 0 1</normal>
              <size>100 100</size>
            </plane>
          </geometry>
          <material>
            <script>
              <uri>file://media/materials/scripts/gazebo.material</uri>
              <name>Gazebo/Grey</name>
            </script>
          </material>
        </visual>
        <self_collide>0</self_collide>
        <kinematic>0</kinematic>
      </link>
      <pose frame=''>0 0 0 0 -0 0</pose>
    </model>
    <model name='asphalt_plane'>
      <static>1</static>
      <link name='link'>
        <collision name='collision'>
          <geometry>
            <box>
              <size>20 20 0.1</size>
            </box>
          </geometry>
          <max_contacts>10</max_contacts>
          <surface>
            <contact>
              <ode/>
            </contact>
            <bounce/>
            <friction>
              <torsional>
                <ode/>
              </torsional>
              <ode/>
            </friction>
          </surface>
        </collision>
        <visual name='visual'>
          <cast_shadows>0</cast_shadows>
          <geometry>
            <box>
              <size>20 20 0.1</size>
            </box>
          </geometry>
          <material>
            <script>
              <uri>model://asphalt_plane/materials/scripts</uri>
              <uri>model://asphalt_plane/materials/textures</uri>
              <name>vrc/asphalt</name>
            </script>
          </material>
        </visual>
        <self_collide>0</self_collide>
        <kinematic>0</kinematic>
      </link>
      <pose frame=''>0 0 0 0 -0 0</pose>
    </model>
    <model name='tunnel_tile_5'>
      <static>1</static>
      <link name='link'>
        <collision name='collision'>
          <geometry>
            <mesh>
              <uri>model://tunnel_tile_5/meshes/tunnel_tile_5.dae</uri>
            </mesh>
          </geometry>
          <max_contacts>10</max_contacts>
          <surface>
            <contact>
              <ode/>
            </contact>
            <bounce/>
            <friction>
              <torsional>
                <ode/>
              </torsional>
              <ode/>
            </friction>
          </surface>
        </collision>
        <collision name='collision_ground'>
          <geometry>
            <box>
              <size>5 20 0.001</size>
            </box>
          </geometry>
          <max_contacts>10</max_contacts>
          <surface>
            <contact>
              <ode/>
            </contact>
            <bounce/>
            <friction>
              <torsional>
                <ode/>
              </torsional>
              <ode/>
            </friction>
          </surface>
        </collision>
        <visual name='visual_chainlink'>
          <geometry>
            <mesh>
              <uri>model://tunnel_tile_5/meshes/tunnel_tile_5.dae</uri>
              <submesh>
                <name>Chainlink</name>
                <center>0</center>
              </submesh>
              <scale>2.005 2.005 2</scale>
            </mesh>
          </geometry>
          <material>
            <diffuse>0 0 0 1</diffuse>
            <specular>0 0 0 1</specular>
            <script>
              <uri>model://tunnel_tile_5/materials/scripts</uri>
              <uri>model://tunnel_tile_5/materials/textures</uri>
              <name>TunnelTile/Chainlink_Diffuse</name>
            </script>
          </material>
        </visual>
        <visual name='visual_ground'>
          <geometry>
            <mesh>
              <uri>model://tunnel_tile_5/meshes/tunnel_tile_5.dae</uri>
              <submesh>
                <name>Ground</name>
                <center>0</center>
              </submesh>
              <scale>2.005 2.005 2</scale>
            </mesh>
          </geometry>
          <material>
            <diffuse>0 0 0 1</diffuse>
            <specular>0 0 0 1</specular>
            <script>
              <uri>model://tunnel_tile_5/materials/scripts</uri>
              <uri>model://tunnel_tile_5/materials/textures</uri>
              <name>TunnelTile/Ground_Diffuse</name>
            </script>
          </material>
        </visual>
        <visual name='visual_wood'>
          <geometry>
            <mesh>
              <uri>model://tunnel_tile_5/meshes/tunnel_tile_5.dae</uri>
              <submesh>
                <name>Wood</name>
                <center>0</center>
              </submesh>
              <scale>2.005 2.005 2</scale>
            </mesh>
          </geometry>
          <material>
            <diffuse>0 0 0 1</diffuse>
            <specular>0 0 0 1</specular>
            <script>
              <uri>model://tunnel_tile_5/materials/scripts</uri>
              <uri>model://tunnel_tile_5/materials/textures</uri>
              <name>TunnelTile/Wood_Diffuse</name>
            </script>
          </material>
        </visual>
        <visual name='visual_walls'>
          <geometry>
            <mesh>
              <uri>model://tunnel_tile_5/meshes/tunnel_tile_5.dae</uri>
              <submesh>
                <name>Walls</name>
                <center>0</center>
              </submesh>
              <scale>2.005 2.005 2</scale>
            </mesh>
          </geometry>
          <material>
            <diffuse>0 0 0 1</diffuse>
            <specular>0 0 0 1</specular>
            <script>
              <uri>model://tunnel_tile_5/materials/scripts</uri>
              <uri>model://tunnel_tile_5/materials/textures</uri>
              <name>TunnelTile/Walls_Diffuse</name>
            </script>
          </material>
        </visual>
        <visual name='visual_lights'>
          <geometry>
            <mesh>
              <uri>model://tunnel_tile_5/meshes/tunnel_tile_5.dae</uri>
              <submesh>
                <name>Lights</name>
                <center>0</center>
              </submesh>
              <scale>2.005 2.005 2</scale>
            </mesh>
          </geometry>
          <material>
            <diffuse>0 0 0 1</diffuse>
            <specular>0 0 0 1</specular>
            <script>
              <uri>model://tunnel_tile_5/materials/scripts</uri>
              <uri>model://tunnel_tile_5/materials/textures</uri>
              <name>TunnelTile/Light_Diffuse</name>
            </script>
          </material>
        </visual>
        <self_collide>0</self_collide>
        <kinematic>0</kinematic>
      </link>
      <pose frame=''>0 0 0 0 -0 1.5708</pose>
    </model>
    <model name='iris_opt_flow'>
      <link name='iris::base_link'>
        <pose frame=''>0 0 0 0 -0 0</pose>
        <inertial>
          <pose frame=''>0 0 0 0 -0 0</pose>
          <mass>1.5</mass>
          <inertia>
            <ixx>0.0347563</ixx>
            <ixy>0</ixy>
            <ixz>0</ixz>
            <iyy>0.0458929</iyy>
            <iyz>0</iyz>
            <izz>0.0977</izz>
          </inertia>
        </inertial>
        <collision name='base_link_inertia_collision'>
          <pose frame=''>0 0 0 0 -0 0</pose>
          <geometry>
            <box>
              <size>0.47 0.47 0.11</size>
            </box>
          </geometry>
          <surface>
            <contact>
              <ode>
                <min_depth>0.001</min_depth>
                <max_vel>0</max_vel>
              </ode>
            </contact>
            <friction>
              <ode/>
              <torsional>
                <ode/>
              </torsional>
            </friction>
            <bounce/>
          </surface>
          <max_contacts>10</max_contacts>
        </collision>
        <visual name='base_link_inertia_visual'>
          <pose frame=''>0 0 0 0 -0 0</pose>
          <geometry>
            <mesh>
              <scale>1 1 1</scale>
              <uri>model://rotors_description/meshes/iris.stl</uri>
            </mesh>
          </geometry>
          <material>
            <script>
              <name>Gazebo/DarkGrey</name>
              <uri>file://media/materials/scripts/gazebo.material</uri>
            </script>
          </material>
        </visual>
        <gravity>1</gravity>
        <velocity_decay/>
        <self_collide>0</self_collide>
        <kinematic>0</kinematic>
      </link>
      <link name='iris::/imu_link'>
        <pose frame=''>0 0 0 0 -0 0</pose>
        <inertial>
          <pose frame=''>0 0 0 0 -0 0</pose>
          <mass>0.015</mass>
          <inertia>
            <ixx>1e-05</ixx>
            <ixy>0</ixy>
            <ixz>0</ixz>
            <iyy>1e-05</iyy>
            <iyz>0</iyz>
            <izz>1e-05</izz>
          </inertia>
        </inertial>
        <self_collide>0</self_collide>
        <kinematic>0</kinematic>
      </link>
      <joint name='iris::/imu_joint' type='revolute'>
        <child>iris::/imu_link</child>
        <parent>iris::base_link</parent>
        <axis>
          <xyz>1 0 0</xyz>
          <limit>
            <lower>0</lower>
            <upper>0</upper>
            <effort>0</effort>
            <velocity>0</velocity>
          </limit>
          <dynamics>
            <spring_reference>0</spring_reference>
            <spring_stiffness>0</spring_stiffness>
          </dynamics>
          <use_parent_model_frame>1</use_parent_model_frame>
        </axis>
      </joint>
      <link name='iris::rotor_0'>
        <pose frame=''>0.13 -0.22 0.023 0 -0 0</pose>
        <inertial>
          <pose frame=''>0 0 0 0 -0 0</pose>
          <mass>0.005</mass>
          <inertia>
            <ixx>9.75e-07</ixx>
            <ixy>0</ixy>
            <ixz>0</ixz>
            <iyy>0.000273104</iyy>
            <iyz>0</iyz>
            <izz>0.000274004</izz>
          </inertia>
        </inertial>
        <collision name='rotor_0_collision'>
          <pose frame=''>0 0 0 0 -0 0</pose>
          <geometry>
            <cylinder>
              <length>0.005</length>
              <radius>0.128</radius>
            </cylinder>
          </geometry>
          <surface>
            <contact>
              <ode/>
            </contact>
            <friction>
              <ode/>
              <torsional>
                <ode/>
              </torsional>
            </friction>
            <bounce/>
          </surface>
          <max_contacts>10</max_contacts>
        </collision>
        <visual name='rotor_0_visual'>
          <pose frame=''>0 0 0 0 -0 0</pose>
          <geometry>
            <mesh>
              <scale>1 1 1</scale>
              <uri>model://rotors_description/meshes/iris_prop_ccw.dae</uri>
            </mesh>
          </geometry>
          <material>
            <script>
              <name>Gazebo/Blue</name>
              <uri>file://media/materials/scripts/gazebo.material</uri>
            </script>
          </material>
        </visual>
        <gravity>1</gravity>
        <velocity_decay/>
        <self_collide>0</self_collide>
        <kinematic>0</kinematic>
      </link>
      <joint name='iris::rotor_0_joint' type='revolute'>
        <child>iris::rotor_0</child>
        <parent>iris::base_link</parent>
        <axis>
          <xyz>0 0 1</xyz>
          <limit>
            <lower>-1e+16</lower>
            <upper>1e+16</upper>
          </limit>
          <dynamics>
            <spring_reference>0</spring_reference>
            <spring_stiffness>0</spring_stiffness>
          </dynamics>
          <use_parent_model_frame>1</use_parent_model_frame>
        </axis>
      </joint>
      <link name='iris::rotor_1'>
        <pose frame=''>-0.13 0.2 0.023 0 -0 0</pose>
        <inertial>
          <pose frame=''>0 0 0 0 -0 0</pose>
          <mass>0.005</mass>
          <inertia>
            <ixx>9.75e-07</ixx>
            <ixy>0</ixy>
            <ixz>0</ixz>
            <iyy>0.000273104</iyy>
            <iyz>0</iyz>
            <izz>0.000274004</izz>
          </inertia>
        </inertial>
        <collision name='rotor_1_collision'>
          <pose frame=''>0 0 0 0 -0 0</pose>
          <geometry>
            <cylinder>
              <length>0.005</length>
              <radius>0.128</radius>
            </cylinder>
          </geometry>
          <surface>
            <contact>
              <ode/>
            </contact>
            <friction>
              <ode/>
              <torsional>
                <ode/>
              </torsional>
            </friction>
            <bounce/>
          </surface>
          <max_contacts>10</max_contacts>
        </collision>
        <visual name='rotor_1_visual'>
          <pose frame=''>0 0 0 0 -0 0</pose>
          <geometry>
            <mesh>
              <scale>1 1 1</scale>
              <uri>model://rotors_description/meshes/iris_prop_ccw.dae</uri>
            </mesh>
          </geometry>
          <material>
            <script>
              <name>Gazebo/DarkGrey</name>
              <uri>file://media/materials/scripts/gazebo.material</uri>
            </script>
          </material>
        </visual>
        <gravity>1</gravity>
        <velocity_decay/>
        <self_collide>0</self_collide>
        <kinematic>0</kinematic>
      </link>
      <joint name='iris::rotor_1_joint' type='revolute'>
        <child>iris::rotor_1</child>
        <parent>iris::base_link</parent>
        <axis>
          <xyz>0 0 1</xyz>
          <limit>
            <lower>-1e+16</lower>
            <upper>1e+16</upper>
          </limit>
          <dynamics>
            <spring_reference>0</spring_reference>
            <spring_stiffness>0</spring_stiffness>
          </dynamics>
          <use_parent_model_frame>1</use_parent_model_frame>
        </axis>
      </joint>
      <link name='iris::rotor_2'>
        <pose frame=''>0.13 0.22 0.023 0 -0 0</pose>
        <inertial>
          <pose frame=''>0 0 0 0 -0 0</pose>
          <mass>0.005</mass>
          <inertia>
            <ixx>9.75e-07</ixx>
            <ixy>0</ixy>
            <ixz>0</ixz>
            <iyy>0.000273104</iyy>
            <iyz>0</iyz>
            <izz>0.000274004</izz>
          </inertia>
        </inertial>
        <collision name='rotor_2_collision'>
          <pose frame=''>0 0 0 0 -0 0</pose>
          <geometry>
            <cylinder>
              <length>0.005</length>
              <radius>0.128</radius>
            </cylinder>
          </geometry>
          <surface>
            <contact>
              <ode/>
            </contact>
            <friction>
              <ode/>
              <torsional>
                <ode/>
              </torsional>
            </friction>
            <bounce/>
          </surface>
          <max_contacts>10</max_contacts>
        </collision>
        <visual name='rotor_2_visual'>
          <pose frame=''>0 0 0 0 -0 0</pose>
          <geometry>
            <mesh>
              <scale>1 1 1</scale>
              <uri>model://rotors_description/meshes/iris_prop_cw.dae</uri>
            </mesh>
          </geometry>
          <material>
            <script>
              <name>Gazebo/Blue</name>
              <uri>file://media/materials/scripts/gazebo.material</uri>
            </script>
          </material>
        </visual>
        <gravity>1</gravity>
        <velocity_decay/>
        <self_collide>0</self_collide>
        <kinematic>0</kinematic>
      </link>
      <joint name='iris::rotor_2_joint' type='revolute'>
        <child>iris::rotor_2</child>
        <parent>iris::base_link</parent>
        <axis>
          <xyz>0 0 1</xyz>
          <limit>
            <lower>-1e+16</lower>
            <upper>1e+16</upper>
          </limit>
          <dynamics>
            <spring_reference>0</spring_reference>
            <spring_stiffness>0</spring_stiffness>
          </dynamics>
          <use_parent_model_frame>1</use_parent_model_frame>
        </axis>
      </joint>
      <link name='iris::rotor_3'>
        <pose frame=''>-0.13 -0.2 0.023 0 -0 0</pose>
        <inertial>
          <pose frame=''>0 0 0 0 -0 0</pose>
          <mass>0.005</mass>
          <inertia>
            <ixx>9.75e-07</ixx>
            <ixy>0</ixy>
            <ixz>0</ixz>
            <iyy>0.000273104</iyy>
            <iyz>0</iyz>
            <izz>0.000274004</izz>
          </inertia>
        </inertial>
        <collision name='rotor_3_collision'>
          <pose frame=''>0 0 0 0 -0 0</pose>
          <geometry>
            <cylinder>
              <length>0.005</length>
              <radius>0.128</radius>
            </cylinder>
          </geometry>
          <surface>
            <contact>
              <ode/>
            </contact>
            <friction>
              <ode/>
              <torsional>
                <ode/>
              </torsional>
            </friction>
            <bounce/>
          </surface>
          <max_contacts>10</max_contacts>
        </collision>
        <visual name='rotor_3_visual'>
          <pose frame=''>0 0 0 0 -0 0</pose>
          <geometry>
            <mesh>
              <scale>1 1 1</scale>
              <uri>model://rotors_description/meshes/iris_prop_cw.dae</uri>
            </mesh>
          </geometry>
          <material>
            <script>
              <name>Gazebo/DarkGrey</name>
              <uri>file://media/materials/scripts/gazebo.material</uri>
            </script>
          </material>
        </visual>
        <gravity>1</gravity>
        <velocity_decay/>
        <self_collide>0</self_collide>
        <kinematic>0</kinematic>
      </link>
      <joint name='iris::rotor_3_joint' type='revolute'>
        <child>iris::rotor_3</child>
        <parent>iris::base_link</parent>
        <axis>
          <xyz>0 0 1</xyz>
          <limit>
            <lower>-1e+16</lower>
            <upper>1e+16</upper>
          </limit>
          <dynamics>
            <spring_reference>0</spring_reference>
            <spring_stiffness>0</spring_stiffness>
          </dynamics>
          <use_parent_model_frame>1</use_parent_model_frame>
        </axis>
      </joint>
      <plugin name='rosbag' filename='libgazebo_multirotor_base_plugin.so'>
        <robotNamespace/>
        <linkName>iris::base_link</linkName>
        <rotorVelocitySlowdownSim>10</rotorVelocitySlowdownSim>
      </plugin>
      <plugin name='front_right_motor_model' filename='libgazebo_motor_model.so'>
        <robotNamespace/>
        <jointName>iris::rotor_0_joint</jointName>
        <linkName>iris::rotor_0</linkName>
        <turningDirection>ccw</turningDirection>
        <timeConstantUp>0.0125</timeConstantUp>
        <timeConstantDown>0.025</timeConstantDown>
        <maxRotVelocity>1100</maxRotVelocity>
        <motorConstant>8.54858e-06</motorConstant>
        <momentConstant>0.06</momentConstant>
        <commandSubTopic>/gazebo/command/motor_speed</commandSubTopic>
        <motorNumber>0</motorNumber>
        <rotorDragCoefficient>0.000806428</rotorDragCoefficient>
        <rollingMomentCoefficient>1e-06</rollingMomentCoefficient>
        <motorSpeedPubTopic>/motor_speed/0</motorSpeedPubTopic>
        <rotorVelocitySlowdownSim>10</rotorVelocitySlowdownSim>
      </plugin>
      <plugin name='back_left_motor_model' filename='libgazebo_motor_model.so'>
        <robotNamespace/>
        <jointName>iris::rotor_1_joint</jointName>
        <linkName>iris::rotor_1</linkName>
        <turningDirection>ccw</turningDirection>
        <timeConstantUp>0.0125</timeConstantUp>
        <timeConstantDown>0.025</timeConstantDown>
        <maxRotVelocity>1100</maxRotVelocity>
        <motorConstant>8.54858e-06</motorConstant>
        <momentConstant>0.06</momentConstant>
        <commandSubTopic>/gazebo/command/motor_speed</commandSubTopic>
        <motorNumber>1</motorNumber>
        <rotorDragCoefficient>0.000806428</rotorDragCoefficient>
        <rollingMomentCoefficient>1e-06</rollingMomentCoefficient>
        <motorSpeedPubTopic>/motor_speed/1</motorSpeedPubTopic>
        <rotorVelocitySlowdownSim>10</rotorVelocitySlowdownSim>
      </plugin>
      <plugin name='front_left_motor_model' filename='libgazebo_motor_model.so'>
        <robotNamespace/>
        <jointName>iris::rotor_2_joint</jointName>
        <linkName>iris::rotor_2</linkName>
        <turningDirection>cw</turningDirection>
        <timeConstantUp>0.0125</timeConstantUp>
        <timeConstantDown>0.025</timeConstantDown>
        <maxRotVelocity>1100</maxRotVelocity>
        <motorConstant>8.54858e-06</motorConstant>
        <momentConstant>0.06</momentConstant>
        <commandSubTopic>/gazebo/command/motor_speed</commandSubTopic>
        <motorNumber>2</motorNumber>
        <rotorDragCoefficient>0.000806428</rotorDragCoefficient>
        <rollingMomentCoefficient>1e-06</rollingMomentCoefficient>
        <motorSpeedPubTopic>/motor_speed/2</motorSpeedPubTopic>
        <rotorVelocitySlowdownSim>10</rotorVelocitySlowdownSim>
      </plugin>
      <plugin name='back_right_motor_model' filename='libgazebo_motor_model.so'>
        <robotNamespace/>
        <jointName>iris::rotor_3_joint</jointName>
        <linkName>iris::rotor_3</linkName>
        <turningDirection>cw</turningDirection>
        <timeConstantUp>0.0125</timeConstantUp>
        <timeConstantDown>0.025</timeConstantDown>
        <maxRotVelocity>1100</maxRotVelocity>
        <motorConstant>8.54858e-06</motorConstant>
        <momentConstant>0.06</momentConstant>
        <commandSubTopic>/gazebo/command/motor_speed</commandSubTopic>
        <motorNumber>3</motorNumber>
        <rotorDragCoefficient>0.000806428</rotorDragCoefficient>
        <rollingMomentCoefficient>1e-06</rollingMomentCoefficient>
        <motorSpeedPubTopic>/motor_speed/3</motorSpeedPubTopic>
        <rotorVelocitySlowdownSim>10</rotorVelocitySlowdownSim>
      </plugin>
      <plugin name='gps_plugin' filename='libgazebo_gps_plugin.so'>
        <robotNamespace/>
        <gpsNoise>true</gpsNoise>
      </plugin>
      <plugin name='mavlink_interface' filename='libgazebo_mavlink_interface.so'>
        <robotNamespace/>
        <imuSubTopic>/imu</imuSubTopic>
        <gpsSubTopic>/gps</gpsSubTopic>
        <mavlink_addr>INADDR_ANY</mavlink_addr>
        <mavlink_udp_port>14560</mavlink_udp_port>
        <serialEnabled>false</serialEnabled>
        <serialDevice>/dev/ttyACM0</serialDevice>
        <baudRate>921600</baudRate>
        <qgc_addr>INADDR_ANY</qgc_addr>
        <qgc_udp_port>14550</qgc_udp_port>
        <hil_mode>false</hil_mode>
        <hil_state_level>false</hil_state_level>
        <vehicle_is_tailsitter>false</vehicle_is_tailsitter>
        <send_vision_estimation>true</send_vision_estimation>
        <send_odometry>false</send_odometry>
        <enable_lockstep>true</enable_lockstep>
        <use_tcp>true</use_tcp>
        <motorSpeedCommandPubTopic>/gazebo/command/motor_speed</motorSpeedCommandPubTopic>
        <control_channels>
          <channel name='rotor1'>
            <input_index>0</input_index>
            <input_offset>0</input_offset>
            <input_scaling>1000</input_scaling>
            <zero_position_disarmed>0</zero_position_disarmed>
            <zero_position_armed>100</zero_position_armed>
            <joint_control_type>velocity</joint_control_type>
          </channel>
          <channel name='rotor2'>
            <input_index>1</input_index>
            <input_offset>0</input_offset>
            <input_scaling>1000</input_scaling>
            <zero_position_disarmed>0</zero_position_disarmed>
            <zero_position_armed>100</zero_position_armed>
            <joint_control_type>velocity</joint_control_type>
          </channel>
          <channel name='rotor3'>
            <input_index>2</input_index>
            <input_offset>0</input_offset>
            <input_scaling>1000</input_scaling>
            <zero_position_disarmed>0</zero_position_disarmed>
            <zero_position_armed>100</zero_position_armed>
            <joint_control_type>velocity</joint_control_type>
          </channel>
          <channel name='rotor4'>
            <input_index>3</input_index>
            <input_offset>0</input_offset>
            <input_scaling>1000</input_scaling>
            <zero_position_disarmed>0</zero_position_disarmed>
            <zero_position_armed>100</zero_position_armed>
            <joint_control_type>velocity</joint_control_type>
          </channel>
          <channel name='rotor5'>
            <input_index>4</input_index>
            <input_offset>1</input_offset>
            <input_scaling>324.6</input_scaling>
            <zero_position_disarmed>0</zero_position_disarmed>
            <zero_position_armed>0</zero_position_armed>
            <joint_control_type>velocity</joint_control_type>
            <joint_control_pid>
              <p>0.1</p>
              <i>0</i>
              <d>0</d>
              <iMax>0.0</iMax>
              <iMin>0.0</iMin>
              <cmdMax>2</cmdMax>
              <cmdMin>-2</cmdMin>
            </joint_control_pid>
            <joint_name>zephyr_delta_wing::propeller_joint</joint_name>
          </channel>
          <channel name='rotor6'>
            <input_index>5</input_index>
            <input_offset>0</input_offset>
            <input_scaling>0.524</input_scaling>
            <zero_position_disarmed>0</zero_position_disarmed>
            <zero_position_armed>0</zero_position_armed>
            <joint_control_type>position</joint_control_type>
            <joint_name>zephyr_delta_wing::flap_left_joint</joint_name>
            <joint_control_pid>
              <p>10.0</p>
              <i>0</i>
              <d>0</d>
              <iMax>0</iMax>
              <iMin>0</iMin>
              <cmdMax>20</cmdMax>
              <cmdMin>-20</cmdMin>
            </joint_control_pid>
          </channel>
          <channel name='rotor7'>
            <input_index>6</input_index>
            <input_offset>0</input_offset>
            <input_scaling>0.524</input_scaling>
            <zero_position_disarmed>0</zero_position_disarmed>
            <zero_position_armed>0</zero_position_armed>
            <joint_control_type>position</joint_control_type>
            <joint_name>zephyr_delta_wing::flap_right_joint</joint_name>
            <joint_control_pid>
              <p>10.0</p>
              <i>0</i>
              <d>0</d>
              <iMax>0</iMax>
              <iMin>0</iMin>
              <cmdMax>20</cmdMax>
              <cmdMin>-20</cmdMin>
            </joint_control_pid>
          </channel>
          <channel name='rotor8'>
            <input_index>7</input_index>
            <input_offset>0</input_offset>
            <input_scaling>0.524</input_scaling>
            <zero_position_disarmed>0</zero_position_disarmed>
            <zero_position_armed>0</zero_position_armed>
            <joint_control_type>position</joint_control_type>
          </channel>
        </control_channels>
      </plugin>
      <static>0</static>
      <plugin name='rotors_gazebo_imu_plugin' filename='libgazebo_imu_plugin.so'>
        <robotNamespace/>
        <linkName>iris::/imu_link</linkName>
        <imuTopic>/imu</imuTopic>
        <gyroscopeNoiseDensity>0.0003394</gyroscopeNoiseDensity>
        <gyroscopeRandomWalk>3.8785e-05</gyroscopeRandomWalk>
        <gyroscopeBiasCorrelationTime>1000.0</gyroscopeBiasCorrelationTime>
        <gyroscopeTurnOnBiasSigma>0.0087</gyroscopeTurnOnBiasSigma>
        <accelerometerNoiseDensity>0.004</accelerometerNoiseDensity>
        <accelerometerRandomWalk>0.006</accelerometerRandomWalk>
        <accelerometerBiasCorrelationTime>300.0</accelerometerBiasCorrelationTime>
        <accelerometerTurnOnBiasSigma>0.196</accelerometerTurnOnBiasSigma>
      </plugin>
      <plugin name='p3d_base_controller' filename='libgazebo_ros_p3d.so'>
        <alwaysOn>true</alwaysOn>
        <updateRate>50.0</updateRate>
        <bodyName>iris::base_link</bodyName>
        <topicName>groundTruth</topicName>
        <gaussianNoise>0.01</gaussianNoise>
        <frameName>world</frameName>
        <xyzOffsets>0 0 0</xyzOffsets>
        <rpyOffsets>0 0 0</rpyOffsets>
      </plugin>
      <link name='px4flow::link'>
        <pose frame=''>0.05 0 -0.05 1.57079 1.57079 3.14159</pose>
        <inertial>
          <mass>0.05</mass>
          <inertia>
            <ixx>4.16667e-06</ixx>
            <iyy>5.20833e-07</iyy>
            <izz>3.85417e-06</izz>
            <ixy>0</ixy>
            <ixz>0</ixz>
            <iyz>0</iyz>
          </inertia>
        </inertial>
        <visual name='visual'>
          <geometry>
            <box>
              <size>0.005 0.03 0.01</size>
            </box>
          </geometry>
        </visual>
        <collision name='collision'>
          <geometry>
            <box>
              <size>0.005 0.03 0.01</size>
            </box>
          </geometry>
          <max_contacts>10</max_contacts>
          <surface>
            <contact>
              <ode/>
            </contact>
            <bounce/>
            <friction>
              <torsional>
                <ode/>
              </torsional>
              <ode/>
            </friction>
          </surface>
        </collision>
        <sensor name='px4flow' type='imu'>
          <pose frame=''>0 0 0 -3e-06 -1.57079 3.14159</pose>
          <always_on>1</always_on>
          <update_rate>200</update_rate>
        </sensor>
        <sensor name='px4flow' type='camera'>
          <always_on>1</always_on>
          <update_rate>100</update_rate>
          <visualize>1</visualize>
          <topic>/px4flow</topic>
          <camera name='__default__'>
            <horizontal_fov>0.25</horizontal_fov>
            <lens>
              <type>gnomonical</type>
              <scale_to_hfov>0</scale_to_hfov>
            </lens>
            <image>
              <width>64</width>
              <height>64</height>
              <format>L8</format>
            </image>
            <clip>
              <near>0.1</near>
              <far>100</far>
            </clip>
            <noise>
              <type>gaussian</type>
              <mean>0</mean>
              <stddev>0.001</stddev>
            </noise>
          </camera>
          <plugin name='opticalflow_plugin' filename='libgazebo_opticalflow_plugin.so'>
            <robotNamespace/>
            <outputRate>20</outputRate>
            <hasGyro>true</hasGyro>
            <gyroTopic>/px4flow/imu</gyroTopic>
          </plugin>
        </sensor>
        <self_collide>0</self_collide>
        <kinematic>0</kinematic>
      </link>
      <joint name='px4flow_joint' type='revolute'>
        <parent>iris::base_link</parent>
        <child>px4flow::link</child>
        <axis>
          <xyz>0 0 1</xyz>
          <limit>
            <upper>0</upper>
            <lower>0</lower>
          </limit>
          <use_parent_model_frame>0</use_parent_model_frame>
          <dynamics>
            <spring_reference>0</spring_reference>
            <spring_stiffness>0</spring_stiffness>
          </dynamics>
        </axis>
      </joint>
      <link name='sf10a::link'>
        <inertial>
          <mass>0.05</mass>
          <inertia>
            <ixx>2.08333e-07</ixx>
            <iyy>5.20833e-07</iyy>
            <izz>5.20833e-07</izz>
            <ixy>0</ixy>
            <ixz>0</ixz>
            <iyz>0</iyz>
          </inertia>
        </inertial>
        <visual name='visual'>
          <geometry>
            <box>
              <size>0.01 0.005 0.005</size>
            </box>
          </geometry>
          <material>
            <script>
              <name>Gazebo/Blue</name>
              <uri>file://media/materials/scripts/gazebo.material</uri>
            </script>
          </material>
        </visual>
        <collision name='collision'>
          <geometry>
            <box>
              <size>0.01 0.005 0.005</size>
            </box>
          </geometry>
          <max_contacts>10</max_contacts>
          <surface>
            <contact>
              <ode/>
            </contact>
            <bounce/>
            <friction>
              <torsional>
                <ode/>
              </torsional>
              <ode/>
            </friction>
          </surface>
        </collision>
        <sensor name='sf10a' type='ray'>
          <visualize>1</visualize>
          <always_on>1</always_on>
          <update_rate>20</update_rate>
          <pose frame=''>0 0 0 3.14159 1.57079 3.14159</pose>
          <ray>
            <scan>
              <horizontal>
                <samples>1</samples>
                <resolution>1</resolution>
                <min_angle>-0</min_angle>
                <max_angle>0</max_angle>
              </horizontal>
              <vertical>
                <samples>1</samples>
                <min_angle>0</min_angle>
                <max_angle>0</max_angle>
              </vertical>
            </scan>
            <range>
              <min>0.06</min>
              <max>35</max>
              <resolution>0.01</resolution>
            </range>
            <noise>
              <type>gaussian</type>
              <mean>0</mean>
              <stddev>0.01</stddev>
            </noise>
          </ray>
          <plugin name='LaserPlugin' filename='libgazebo_lidar_plugin.so'>
            <robotNamespace/>
            <min_distance>0.1</min_distance>
            <max_distance>25.0</max_distance>
          </plugin>
        </sensor>
        <pose frame=''>0 0 -0.05 0 -0 0</pose>
        <self_collide>0</self_collide>
        <kinematic>0</kinematic>
      </link>
      <joint name='sf10a_joint' type='fixed'>
        <parent>iris::base_link</parent>
        <child>sf10a::link</child>
      </joint>
      <pose frame=''>1 0 0 0 -0 0</pose>
    </model>
    <physics name='default_physics' default='0' type='ode'>
      <real_time_update_rate>0</real_time_update_rate>
      <ode>
        <solver>
          <type>quick</type>
          <iters>10</iters>
          <sor>1.3</sor>
          <island_threads>5</island_threads>
          <thread_position_correction>1</thread_position_correction>
          <use_dynamic_moi_rescaling>0</use_dynamic_moi_rescaling>
        </solver>
        <constraints>
          <cfm>0</cfm>
          <erp>0.2</erp>
          <contact_max_correcting_vel>0.1</contact_max_correcting_vel>
          <contact_surface_layer>0</contact_surface_layer>
        </constraints>
      </ode>
      <max_step_size>0.004</max_step_size>
      <real_time_factor>1</real_time_factor>
      <real_time_update_rate>250</real_time_update_rate>
    </physics>
    <gui fullscreen='0'>
      <camera name='user_camera'>
        <pose frame=''>-10 0 6 0 0.3 0</pose>
        <view_controller>orbit</view_controller>
        <projection_type>perspective</projection_type>
      </camera>
    </gui>
    <model name='jersey_barrier'>
      <static>1</static>
      <link name='link'>
        <visual name='visual'>
          <geometry>
            <mesh>
              <uri>model://jersey_barrier/meshes/jersey_barrier.dae</uri>
            </mesh>
          </geometry>
        </visual>
        <collision name='upright'>
          <pose frame=''>0 0 0.5715 0 -0 0</pose>
          <geometry>
            <box>
              <size>4.06542 0.3063 1.143</size>
            </box>
          </geometry>
          <max_contacts>10</max_contacts>
          <surface>
            <bounce/>
            <friction>
              <ode/>
              <torsional>
                <ode/>
              </torsional>
            </friction>
            <contact>
              <ode/>
            </contact>
          </surface>
        </collision>
        <collision name='base'>
          <pose frame=''>0 0 0.032258 0 -0 0</pose>
          <geometry>
            <box>
              <size>4.06542 0.8107 0.064516</size>
            </box>
          </geometry>
          <max_contacts>10</max_contacts>
          <surface>
            <bounce/>
            <friction>
              <ode/>
              <torsional>
                <ode/>
              </torsional>
            </friction>
            <contact>
              <ode/>
            </contact>
          </surface>
        </collision>
        <collision name='base2'>
          <pose frame=''>0 0 0.1 0 -0 0</pose>
          <geometry>
            <box>
              <size>4.06542 0.65 0.1</size>
            </box>
          </geometry>
          <max_contacts>10</max_contacts>
          <surface>
            <bounce/>
            <friction>
              <ode/>
              <torsional>
                <ode/>
              </torsional>
            </friction>
            <contact>
              <ode/>
            </contact>
          </surface>
        </collision>
        <collision name='base3'>
          <pose frame=''>0 0 0.2 0 -0 0</pose>
          <geometry>
            <box>
              <size>4.06542 0.5 0.1</size>
            </box>
          </geometry>
          <max_contacts>10</max_contacts>
          <surface>
            <bounce/>
            <friction>
              <ode/>
              <torsional>
                <ode/>
              </torsional>
            </friction>
            <contact>
              <ode/>
            </contact>
          </surface>
        </collision>
        <collision name='left-angle'>
          <pose frame=''>0 -0.224 0.2401 0.9 -0 0</pose>
          <geometry>
            <box>
              <size>4.06542 0.5 0.064516</size>
            </box>
          </geometry>
          <max_contacts>10</max_contacts>
          <surface>
            <bounce/>
            <friction>
              <ode/>
              <torsional>
                <ode/>
              </torsional>
            </friction>
            <contact>
              <ode/>
            </contact>
          </surface>
        </collision>
        <collision name='right-angle'>
          <pose frame=''>0 0.224 0.2401 -0.9 0 0</pose>
          <geometry>
            <box>
              <size>4.06542 0.5 0.064516</size>
            </box>
          </geometry>
          <max_contacts>10</max_contacts>
          <surface>
            <bounce/>
            <friction>
              <ode/>
              <torsional>
                <ode/>
              </torsional>
            </friction>
            <contact>
              <ode/>
            </contact>
          </surface>
        </collision>
        <velocity_decay>
          <linear>0</linear>
          <angular>0</angular>
        </velocity_decay>
        <self_collide>0</self_collide>
        <kinematic>0</kinematic>
        <gravity>1</gravity>
      </link>
      <pose frame=''>-8 -10 0 0 -0 0</pose>
    </model>
    <gravity>0 0 -9.8066</gravity>
    <magnetic_field>6e-06 2.3e-05 -4.2e-05</magnetic_field>
    <atmosphere type='adiabatic'/>
    <scene>
      <ambient>0.4 0.4 0.4 1</ambient>
      <background>0.7 0.7 0.7 1</background>
      <shadows>1</shadows>
    </scene>
    <spherical_coordinates>
      <surface_model>EARTH_WGS84</surface_model>
      <latitude_deg>0</latitude_deg>
      <longitude_deg>0</longitude_deg>
      <elevation>0</elevation>
      <heading_deg>0</heading_deg>
    </spherical_coordinates>
    <model name='/'>
      <link name='base_link'>
        <pose frame=''>0 0 0 0 -0 0</pose>
        <inertial>
          <pose frame=''>-0.004528 -0.083176 0.07505 0 -0 0</pose>
          <mass>47.044</mass>
          <inertia>
            <ixx>0.976608</ixx>
            <ixy>-0.00847023</ixy>
            <ixz>-0.0115031</ixz>
            <iyy>2.13821</iyy>
            <iyz>-0.0525894</iyz>
            <izz>2.06998</izz>
          </inertia>
        </inertial>
        <collision name='base_link_collision'>
          <pose frame=''>0 0 0.061875 0 -0 0</pose>
          <geometry>
            <box>
              <size>0.9874 0.5709 0.12375</size>
            </box>
          </geometry>
          <max_contacts>10</max_contacts>
          <surface>
            <contact>
              <ode/>
            </contact>
            <bounce/>
            <friction>
              <torsional>
                <ode/>
              </torsional>
              <ode/>
            </friction>
          </surface>
        </collision>
        <collision name='base_link_collision_1'>
          <pose frame=''>0 0 0.175625 0 -0 0</pose>
          <geometry>
            <box>
              <size>0.78992 0.5709 0.10375</size>
            </box>
          </geometry>
          <max_contacts>10</max_contacts>
          <surface>
            <contact>
              <ode/>
            </contact>
            <bounce/>
            <friction>
              <torsional>
                <ode/>
              </torsional>
              <ode/>
            </friction>
          </surface>
        </collision>
        <collision name='base_link_fixed_joint_lump__camera_link_collision_2'>
          <pose frame=''>-0.2 0 1 3.14159 -1.57079 3.14159</pose>
          <geometry>
            <box>
              <size>0.03 0.03 0.03</size>
            </box>
          </geometry>
          <surface>
            <contact>
              <ode/>
            </contact>
            <friction>
              <ode/>
              <torsional>
                <ode/>
              </torsional>
            </friction>
            <bounce/>
          </surface>
          <max_contacts>10</max_contacts>
        </collision>
        <collision name='base_link_fixed_joint_lump__computer_link_collision_3'>
          <pose frame=''>-0.15 0 0.35125 0 -0 0</pose>
          <geometry>
            <box>
              <size>0.2 0.4709 0.2</size>
            </box>
          </geometry>
          <max_contacts>10</max_contacts>
          <surface>
            <contact>
              <ode/>
            </contact>
            <bounce/>
            <friction>
              <torsional>
                <ode/>
              </torsional>
              <ode/>
            </friction>
          </surface>
        </collision>
        <collision name='base_link_fixed_joint_lump__top_plate_link_collision_4'>
          <pose frame=''>0.0812 0 0.245 0 -0 0</pose>
          <geometry>
            <mesh>
              <scale>1 1 1</scale>
              <uri>/opt/ros/kinetic/share/husky_description/meshes/top_plate.stl</uri>
            </mesh>
          </geometry>
          <max_contacts>10</max_contacts>
          <surface>
            <contact>
              <ode/>
            </contact>
            <bounce/>
            <friction>
              <torsional>
                <ode/>
              </torsional>
              <ode/>
            </friction>
          </surface>
        </collision>
        <collision name='base_link_fixed_joint_lump__velodyne_base_link_collision_5'>
          <pose frame=''>-0.181334 -3e-05 0.669663 -0 -0.2618 3.14</pose>
          <geometry>
            <cylinder>
              <length>0.14424</length>
              <radius>0.04267</radius>
            </cylinder>
          </geometry>
          <max_contacts>10</max_contacts>
          <surface>
            <contact>
              <ode/>
            </contact>
            <bounce/>
            <friction>
              <torsional>
                <ode/>
              </torsional>
              <ode/>
            </friction>
          </surface>
        </collision>
        <visual name='base_link_visual'>
          <pose frame=''>0 0 0 0 -0 0</pose>
          <geometry>
            <mesh>
              <scale>1 1 1</scale>
              <uri>/opt/ros/kinetic/share/husky_description/meshes/base_link.dae</uri>
            </mesh>
          </geometry>
        </visual>
        <visual name='base_link_fixed_joint_lump__camera_link_visual_1'>
          <pose frame=''>-0.2 0 1 3.14159 -1.57079 3.14159</pose>
          <geometry>
            <box>
              <size>0.03 0.03 0.03</size>
            </box>
          </geometry>
          <material>
            <script>
              <uri>__default__</uri>
              <name>__default__</name>
            </script>
          </material>
        </visual>
        <visual name='base_link_fixed_joint_lump__computer_link_visual_2'>
          <pose frame=''>-0.15 0 0.35125 0 -0 0</pose>
          <geometry>
            <box>
              <size>0.2 0.4709 0.2</size>
            </box>
          </geometry>
        </visual>
        <visual name='base_link_fixed_joint_lump__front_bumper_link_visual_3'>
          <pose frame=''>0.48 0 0.091 0 -0 0</pose>
          <geometry>
            <mesh>
              <scale>1 1 1</scale>
              <uri>/opt/ros/kinetic/share/husky_description/meshes/bumper.dae</uri>
            </mesh>
          </geometry>
        </visual>
        <visual name='base_link_fixed_joint_lump__rear_bumper_link_visual_4'>
          <pose frame=''>-0.48 0 0.091 0 -0 3.14159</pose>
          <geometry>
            <mesh>
              <scale>1 1 1</scale>
              <uri>/opt/ros/kinetic/share/husky_description/meshes/bumper.dae</uri>
            </mesh>
          </geometry>
        </visual>
        <visual name='base_link_fixed_joint_lump__top_chassis_link_visual_5'>
          <pose frame=''>0 0 0 0 -0 0</pose>
          <geometry>
            <mesh>
              <scale>1 1 1</scale>
              <uri>/opt/ros/kinetic/share/husky_description/meshes/top_chassis.dae</uri>
            </mesh>
          </geometry>
        </visual>
        <visual name='base_link_fixed_joint_lump__top_plate_link_visual_6'>
          <pose frame=''>0.0812 0 0.245 0 -0 0</pose>
          <geometry>
            <mesh>
              <scale>1 1 1</scale>
              <uri>/opt/ros/kinetic/share/husky_description/meshes/top_plate.dae</uri>
            </mesh>
          </geometry>
        </visual>
        <visual name='base_link_fixed_joint_lump__user_rail_link_visual_7'>
          <pose frame=''>0.272 0 0.245 0 -0 0</pose>
          <geometry>
            <mesh>
              <scale>1 1 1</scale>
              <uri>/opt/ros/kinetic/share/husky_description/meshes/user_rail.dae</uri>
            </mesh>
          </geometry>
        </visual>
        <visual name='base_link_fixed_joint_lump__velodyne_base_link_visual_8'>
          <pose frame=''>-0.2 0 0.6 -0 -0.2618 3.14</pose>
          <geometry>
            <mesh>
              <scale>1 1 1</scale>
              <uri>/home/matteo/catkin_ws/src/velodyne_description/meshes/HDL32E_base.dae</uri>
            </mesh>
          </geometry>
        </visual>
        <visual name='base_link_fixed_joint_lump__velodyne_visual_9'>
          <pose frame=''>-0.2 0 0.6 -0 -0.2618 3.14</pose>
          <geometry>
            <mesh>
              <scale>1 1 1</scale>
              <uri>/home/matteo/catkin_ws/src/velodyne_description/meshes/HDL32E_scan.dae</uri>
            </mesh>
          </geometry>
          <material>
            <script>
              <uri>__default__</uri>
              <name>__default__</name>
            </script>
          </material>
        </visual>
        <velocity_decay/>
        <sensor name='camera1' type='wideanglecamera'>
          <update_rate>10</update_rate>
          <camera name='head'>
            <horizontal_fov>3</horizontal_fov>
            <image>
              <width>2448</width>
              <height>2048</height>
              <format>R8G8B8</format>
            </image>
            <clip>
              <near>0.02</near>
              <far>300</far>
            </clip>
            <noise>
              <type>gaussian</type>
              <mean>0</mean>
              <stddev>0.007</stddev>
            </noise>
            <lens>
              <type>custom</type>
              <custom_function>
                <c1>1.05</c1>
                <c2>4</c2>
                <f>1</f>
                <fun>tan</fun>
              </custom_function>
              <scale_to_hfov>1</scale_to_hfov>
              <cutoff_angle>3.1415</cutoff_angle>
              <env_texture_size>512</env_texture_size>
            </lens>
          </camera>
          <plugin name='camera_controller' filename='libgazebo_ros_camera.so'>
            <alwaysOn>true</alwaysOn>
            <updateRate>0.0</updateRate>
            <cameraName>camera1</cameraName>
            <imageTopicName>image_raw</imageTopicName>
            <cameraInfoTopicName>camera_info</cameraInfoTopicName>
            <frameName>camera_link_optical</frameName>
            <robotNamespace>/</robotNamespace>
          </plugin>
          <pose frame=''>-0.2 0 1 3.14159 -1.57079 3.14159</pose>
        </sensor>
        <velocity_decay/>
        <gravity>1</gravity>
        <velocity_decay/>
        <sensor name='velodyne-HDL32E' type='gpu_ray'>
          <visualize>0</visualize>
          <update_rate>5</update_rate>
          <ray>
            <scan>
              <horizontal>
                <samples>2040</samples>
                <resolution>1</resolution>
                <min_angle>-3.14159</min_angle>
                <max_angle>3.14159</max_angle>
              </horizontal>
              <vertical>
                <samples>128</samples>
                <resolution>1</resolution>
                <min_angle>-0.535292</min_angle>
                <max_angle>0.186227</max_angle>
              </vertical>
            </scan>
            <range>
              <min>0.3</min>
              <max>131</max>
              <resolution>0.001</resolution>
            </range>
            <noise>
              <type>gaussian</type>
              <mean>0</mean>
              <stddev>0</stddev>
            </noise>
          </ray>
          <plugin name='gazebo_ros_laser_controller' filename='libgazebo_ros_velodyne_gpu_laser.so'>
            <topicName>/velodyne_points2</topicName>
            <frameName>velodyne</frameName>
            <min_range>0.3</min_range>
            <max_range>130.0</max_range>
            <gaussianNoise>0.008</gaussianNoise>
            <robotNamespace>/</robotNamespace>
          </plugin>
          <pose frame=''>-0.176497 -3.7e-05 0.687716 -0 -0.2618 3.14</pose>
        </sensor>
        <self_collide>0</self_collide>
        <kinematic>0</kinematic>
      </link>
      <link name='front_left_wheel_link'>
        <pose frame=''>0.256 0.2854 0.03282 0 -0 0</pose>
        <inertial>
          <pose frame=''>0 0 0 0 -0 0</pose>
          <mass>2.637</mass>
          <inertia>
            <ixx>0.02467</ixx>
            <ixy>0</ixy>
            <ixz>0</ixz>
            <iyy>0.04411</iyy>
            <iyz>0</iyz>
            <izz>0.02467</izz>
          </inertia>
        </inertial>
        <collision name='front_left_wheel_link_collision'>
          <pose frame=''>0 0 0 1.57079 -0 0</pose>
          <geometry>
            <cylinder>
              <length>0.1143</length>
              <radius>0.1651</radius>
            </cylinder>
          </geometry>
          <surface>
            <contact>
              <ode>
                <kp>1e+07</kp>
                <kd>1</kd>
              </ode>
            </contact>
            <friction>
              <ode>
                <mu>1</mu>
                <mu2>1</mu2>
                <fdir1>1 0 0</fdir1>
              </ode>
              <torsional>
                <ode/>
              </torsional>
            </friction>
            <bounce/>
          </surface>
          <max_contacts>10</max_contacts>
        </collision>
        <visual name='front_left_wheel_link_visual'>
          <pose frame=''>0 0 0 0 -0 0</pose>
          <geometry>
            <mesh>
              <scale>1 1 1</scale>
              <uri>/opt/ros/kinetic/share/husky_description/meshes/wheel.dae</uri>
            </mesh>
          </geometry>
          <material>
            <script>
              <uri>__default__</uri>
              <name>__default__</name>
            </script>
          </material>
        </visual>
        <gravity>1</gravity>
        <velocity_decay/>
        <self_collide>0</self_collide>
        <kinematic>0</kinematic>
      </link>
      <joint name='front_left_wheel' type='revolute'>
        <child>front_left_wheel_link</child>
        <parent>base_link</parent>
        <axis>
          <xyz>0 1 0</xyz>
          <limit>
            <lower>-1e+16</lower>
            <upper>1e+16</upper>
          </limit>
          <dynamics>
            <spring_reference>0</spring_reference>
            <spring_stiffness>0</spring_stiffness>
          </dynamics>
          <use_parent_model_frame>1</use_parent_model_frame>
        </axis>
      </joint>
      <link name='front_right_wheel_link'>
        <pose frame=''>0.256 -0.2854 0.03282 0 -0 0</pose>
        <inertial>
          <pose frame=''>0 0 0 0 -0 0</pose>
          <mass>2.637</mass>
          <inertia>
            <ixx>0.02467</ixx>
            <ixy>0</ixy>
            <ixz>0</ixz>
            <iyy>0.04411</iyy>
            <iyz>0</iyz>
            <izz>0.02467</izz>
          </inertia>
        </inertial>
        <collision name='front_right_wheel_link_collision'>
          <pose frame=''>0 0 0 1.57079 -0 0</pose>
          <geometry>
            <cylinder>
              <length>0.1143</length>
              <radius>0.1651</radius>
            </cylinder>
          </geometry>
          <surface>
            <contact>
              <ode>
                <kp>1e+07</kp>
                <kd>1</kd>
              </ode>
            </contact>
            <friction>
              <ode>
                <mu>1</mu>
                <mu2>1</mu2>
                <fdir1>1 0 0</fdir1>
              </ode>
              <torsional>
                <ode/>
              </torsional>
            </friction>
            <bounce/>
          </surface>
          <max_contacts>10</max_contacts>
        </collision>
        <visual name='front_right_wheel_link_visual'>
          <pose frame=''>0 0 0 0 -0 0</pose>
          <geometry>
            <mesh>
              <scale>1 1 1</scale>
              <uri>/opt/ros/kinetic/share/husky_description/meshes/wheel.dae</uri>
            </mesh>
          </geometry>
          <material>
            <script>
              <uri>__default__</uri>
              <name>__default__</name>
            </script>
          </material>
        </visual>
        <gravity>1</gravity>
        <velocity_decay/>
        <self_collide>0</self_collide>
        <kinematic>0</kinematic>
      </link>
      <joint name='front_right_wheel' type='revolute'>
        <child>front_right_wheel_link</child>
        <parent>base_link</parent>
        <axis>
          <xyz>0 1 0</xyz>
          <limit>
            <lower>-1e+16</lower>
            <upper>1e+16</upper>
          </limit>
          <dynamics>
            <spring_reference>0</spring_reference>
            <spring_stiffness>0</spring_stiffness>
          </dynamics>
          <use_parent_model_frame>1</use_parent_model_frame>
        </axis>
      </joint>
      <link name='rear_left_wheel_link'>
        <pose frame=''>-0.256 0.2854 0.03282 0 -0 0</pose>
        <inertial>
          <pose frame=''>0 0 0 0 -0 0</pose>
          <mass>2.637</mass>
          <inertia>
            <ixx>0.02467</ixx>
            <ixy>0</ixy>
            <ixz>0</ixz>
            <iyy>0.04411</iyy>
            <iyz>0</iyz>
            <izz>0.02467</izz>
          </inertia>
        </inertial>
        <collision name='rear_left_wheel_link_collision'>
          <pose frame=''>0 0 0 1.57079 -0 0</pose>
          <geometry>
            <cylinder>
              <length>0.1143</length>
              <radius>0.1651</radius>
            </cylinder>
          </geometry>
          <surface>
            <contact>
              <ode>
                <kp>1e+07</kp>
                <kd>1</kd>
              </ode>
            </contact>
            <friction>
              <ode>
                <mu>1</mu>
                <mu2>1</mu2>
                <fdir1>1 0 0</fdir1>
              </ode>
              <torsional>
                <ode/>
              </torsional>
            </friction>
            <bounce/>
          </surface>
          <max_contacts>10</max_contacts>
        </collision>
        <visual name='rear_left_wheel_link_visual'>
          <pose frame=''>0 0 0 0 -0 0</pose>
          <geometry>
            <mesh>
              <scale>1 1 1</scale>
              <uri>/opt/ros/kinetic/share/husky_description/meshes/wheel.dae</uri>
            </mesh>
          </geometry>
          <material>
            <script>
              <uri>__default__</uri>
              <name>__default__</name>
            </script>
          </material>
        </visual>
        <gravity>1</gravity>
        <velocity_decay/>
        <self_collide>0</self_collide>
        <kinematic>0</kinematic>
      </link>
      <joint name='rear_left_wheel' type='revolute'>
        <child>rear_left_wheel_link</child>
        <parent>base_link</parent>
        <axis>
          <xyz>0 1 0</xyz>
          <limit>
            <lower>-1e+16</lower>
            <upper>1e+16</upper>
          </limit>
          <dynamics>
            <spring_reference>0</spring_reference>
            <spring_stiffness>0</spring_stiffness>
          </dynamics>
          <use_parent_model_frame>1</use_parent_model_frame>
        </axis>
      </joint>
      <link name='rear_right_wheel_link'>
        <pose frame=''>-0.256 -0.2854 0.03282 0 -0 0</pose>
        <inertial>
          <pose frame=''>0 0 0 0 -0 0</pose>
          <mass>2.637</mass>
          <inertia>
            <ixx>0.02467</ixx>
            <ixy>0</ixy>
            <ixz>0</ixz>
            <iyy>0.04411</iyy>
            <iyz>0</iyz>
            <izz>0.02467</izz>
          </inertia>
        </inertial>
        <collision name='rear_right_wheel_link_collision'>
          <pose frame=''>0 0 0 1.57079 -0 0</pose>
          <geometry>
            <cylinder>
              <length>0.1143</length>
              <radius>0.1651</radius>
            </cylinder>
          </geometry>
          <surface>
            <contact>
              <ode>
                <kp>1e+07</kp>
                <kd>1</kd>
              </ode>
            </contact>
            <friction>
              <ode>
                <mu>1</mu>
                <mu2>1</mu2>
                <fdir1>1 0 0</fdir1>
              </ode>
              <torsional>
                <ode/>
              </torsional>
            </friction>
            <bounce/>
          </surface>
          <max_contacts>10</max_contacts>
        </collision>
        <visual name='rear_right_wheel_link_visual'>
          <pose frame=''>0 0 0 0 -0 0</pose>
          <geometry>
            <mesh>
              <scale>1 1 1</scale>
              <uri>/opt/ros/kinetic/share/husky_description/meshes/wheel.dae</uri>
            </mesh>
          </geometry>
          <material>
            <script>
              <uri>__default__</uri>
              <name>__default__</name>
            </script>
          </material>
        </visual>
        <gravity>1</gravity>
        <velocity_decay/>
        <self_collide>0</self_collide>
        <kinematic>0</kinematic>
      </link>
      <joint name='rear_right_wheel' type='revolute'>
        <child>rear_right_wheel_link</child>
        <parent>base_link</parent>
        <axis>
          <xyz>0 1 0</xyz>
          <limit>
            <lower>-1e+16</lower>
            <upper>1e+16</upper>
          </limit>
          <dynamics>
            <spring_reference>0</spring_reference>
            <spring_stiffness>0</spring_stiffness>
          </dynamics>
          <use_parent_model_frame>1</use_parent_model_frame>
        </axis>
      </joint>
      <plugin name='gazebo_ros_control' filename='libgazebo_ros_control.so'>
        <robotNamespace>/</robotNamespace>
      </plugin>
      <plugin name='imu_controller' filename='libhector_gazebo_ros_imu.so'>
        <robotNamespace>/</robotNamespace>
        <updateRate>50.0</updateRate>
        <bodyName>base_link</bodyName>
        <topicName>imu/data</topicName>
        <accelDrift>0.005 0.005 0.005</accelDrift>
        <accelGaussianNoise>0.005 0.005 0.005</accelGaussianNoise>
        <rateDrift>0.005 0.005 0.005</rateDrift>
        <rateGaussianNoise>0.005 0.005 0.005</rateGaussianNoise>
        <headingDrift>0.005</headingDrift>
        <headingGaussianNoise>0.005</headingGaussianNoise>
      </plugin>
      <static>0</static>
      <plugin name='gps_controller' filename='libhector_gazebo_ros_gps.so'>
        <robotNamespace>/</robotNamespace>
        <updateRate>40</updateRate>
        <bodyName>base_link</bodyName>
        <frameId>base_link</frameId>
        <topicName>navsat/fix</topicName>
        <velocityTopicName>navsat/vel</velocityTopicName>
        <referenceLatitude>49.9</referenceLatitude>
        <referenceLongitude>8.9</referenceLongitude>
        <referenceHeading>0</referenceHeading>
        <referenceAltitude>0</referenceAltitude>
        <drift>0.0001 0.0001 0.0001</drift>
      </plugin>
      <pose frame=''>0 0 0 0 -0 3.14159</pose>
    </model>
    <model name='Mailbox'>
      <link name='link'>
        <collision name='collision'>
          <geometry>
            <mesh>
              <uri>model://mailbox/meshes/mailbox.dae</uri>
            </mesh>
          </geometry>
          <max_contacts>10</max_contacts>
          <surface>
            <contact>
              <ode/>
            </contact>
            <bounce/>
            <friction>
              <torsional>
                <ode/>
              </torsional>
              <ode/>
            </friction>
          </surface>
        </collision>
        <visual name='visual'>
          <geometry>
            <mesh>
              <uri>model://mailbox/meshes/mailbox.dae</uri>
            </mesh>
          </geometry>
          <material>
            <script>
              <uri>model://mailbox/materials/scripts</uri>
              <uri>model://mailbox/materials/textures</uri>
              <name>Mailbox/Diffuse</name>
            </script>
          </material>
        </visual>
        <self_collide>0</self_collide>
        <inertial>
          <inertia>
            <ixx>1</ixx>
            <ixy>0</ixy>
            <ixz>0</ixz>
            <iyy>1</iyy>
            <iyz>0</iyz>
            <izz>1</izz>
          </inertia>
          <mass>1</mass>
        </inertial>
        <kinematic>0</kinematic>
      </link>
      <pose frame=''>3.36338 2.0733 0 0 -0 0</pose>
    </model>
    <state world_name='default'>
      <sim_time>250 192000000</sim_time>
      <real_time>143 530888787</real_time>
      <wall_time>1580231926 12993660</wall_time>
      <iterations>62548</iterations>
      <model name='/'>
        <pose frame=''>-1.72857 -0.373034 0.182173 0.000223 2e-05 -2.80385</pose>
        <scale>1 1 1</scale>
        <link name='base_link'>
          <pose frame=''>-1.72857 -0.373034 0.182173 0.000223 2e-05 -2.80385</pose>
          <velocity>-0.010515 -0.005615 -0.005408 -0.008 -0.061886 0.00141</velocity>
          <acceleration>-0.284832 -0.177819 1.49218 -0.389066 0.870558 2.24357</acceleration>
          <wrench>-13.3997 -8.3653 70.1983 0 -0 0</wrench>
        </link>
        <link name='front_left_wheel_link'>
          <pose frame=''>-1.87556 -0.727038 0.215119 -0.000833 0.896433 -2.80453</pose>
          <velocity>-0.011147 -0.001971 -0.003279 0.010792 -0.076066 0.017266</velocity>
          <acceleration>-1.008 0.468143 -3.82894 3.10954 -0.338833 0.949639</acceleration>
          <wrench>-2.6581 1.23449 -10.0969 0 -0 0</wrench>
        </link>
        <link name='front_right_wheel_link'>
          <pose frame=''>-2.06468 -0.188556 0.215014 -0.000153 1.00346 -2.80397</pose>
          <velocity>-0.013186 -0.006682 -0.031419 -0.008789 -0.066005 0.001185</velocity>
          <acceleration>0.477125 -0.06139 -11.6767 -0.520488 1.0651 -2.35048</acceleration>
          <wrench>1.25818 -0.161887 -30.7914 0 -0 0</wrench>
        </link>
        <link name='rear_left_wheel_link'>
          <pose frame=''>-1.39251 -0.557413 0.215058 -0.000634 0.872118 -2.80433</pose>
          <velocity>-0.012945 -0.005523 0.00463 0.021799 -0.046738 -0.000817</velocity>
          <acceleration>0.109516 -0.154245 11.7028 -0.84252 1.00216 -2.53848</acceleration>
          <wrench>0.288793 -0.406743 30.8603 0 -0 0</wrench>
        </link>
        <link name='rear_right_wheel_link'>
          <pose frame=''>-1.58163 -0.01894 0.215059 1.6e-05 0.77499 -2.80388</pose>
          <velocity>-0.014614 -0.005797 0.007846 0.019682 -0.044619 0.00356</velocity>
          <acceleration>1.92057 -0.606416 12.428 0.657822 -0.841288 -0.24115</acceleration>
          <wrench>5.06455 -1.59912 32.7726 0 -0 0</wrench>
        </link>
      </model>
      <model name='Mailbox'>
        <pose frame=''>3.36338 2.0733 0.050063 0.000516 -0.002373 3e-06</pose>
        <scale>1 1 1</scale>
        <link name='link'>
          <pose frame=''>3.36338 2.0733 0.050063 0.000516 -0.002373 3e-06</pose>
          <velocity>0 0 0 0 -0 0</velocity>
          <acceleration>9e-06 -3e-06 -0.009329 -0.213768 0.213766 0</acceleration>
          <wrench>9e-06 -3e-06 -0.009329 0 -0 0</wrench>
        </link>
      </model>
      <model name='asphalt_plane'>
        <pose frame=''>0 0 0 0 -0 0</pose>
        <scale>1 1 1</scale>
        <link name='link'>
          <pose frame=''>0 0 0 0 -0 0</pose>
          <velocity>0 0 0 0 -0 0</velocity>
          <acceleration>0 0 0 0 -0 0</acceleration>
          <wrench>0 0 0 0 -0 0</wrench>
        </link>
      </model>
      <model name='ground_plane'>
        <pose frame=''>0 0 0 0 -0 0</pose>
        <scale>1 1 1</scale>
        <link name='link'>
          <pose frame=''>0 0 0 0 -0 0</pose>
          <velocity>0 0 0 0 -0 0</velocity>
          <acceleration>0 0 0 0 -0 0</acceleration>
          <wrench>0 0 0 0 -0 0</wrench>
        </link>
      </model>
      <model name='iris_opt_flow'>
        <pose frame=''>0.986799 0.001329 0.104436 -0.001832 2.8e-05 -0.010365</pose>
        <scale>1 1 1</scale>
        <link name='iris::/imu_link'>
          <pose frame=''>0.986799 0.001332 0.104441 -0.001826 2.8e-05 -0.010364</pose>
          <velocity>6e-06 -0.000169 -0.00022 -0.000321 -4.6e-05 -2.8e-05</velocity>
          <acceleration>-0.000198 -0.001776 0.008584 -0.003289 -0.005346 -0.000255</acceleration>
          <wrench>-3e-06 -2.7e-05 0.000129 0 -0 0</wrench>
        </link>
        <link name='iris::base_link'>
          <pose frame=''>0.986799 0.001329 0.104436 -0.001832 2.8e-05 -0.010365</pose>
          <velocity>-2e-06 -1e-06 5e-06 2.2e-05 -2.9e-05 -0</velocity>
          <acceleration>-0.000262 -4.8e-05 0.000808 0.000894 -0.00476 9e-06</acceleration>
          <wrench>-0.000393 -7.2e-05 0.001212 0 -0 0</wrench>
        </link>
        <link name='iris::rotor_0'>
          <pose frame=''>1.11451 -0.219962 0.127839 -0.001826 6.3e-05 0.00909</pose>
          <velocity>-2e-06 -0.000165 -0.000143 -0.00033 -4.7e-05 0</velocity>
          <acceleration>-0.000206 -0.040806 -0.035585 -0.110844 -0.010362 2.8e-05</acceleration>
          <wrench>-1e-06 -0.000204 -0.000178 0 -0 0</wrench>
        </link>
        <link name='iris::rotor_1'>
          <pose frame=''>0.858879 0.20271 0.127079 -0.001826 3.7e-05 -0.005244</pose>
          <velocity>1e-05 -0.000158 -0.000291 -0.000316 -4.6e-05 0</velocity>
          <acceleration>0.002724 -0.039103 -0.07374 -0.070101 -0.008847 2.3e-05</acceleration>
          <wrench>1.4e-05 -0.000196 -0.000369 0 -0 0</wrench>
        </link>
        <link name='iris::rotor_2'>
          <pose frame=''>1.11907 0.220014 0.127036 -0.001826 7.5e-05 0.015565</pose>
          <velocity>1.1e-05 -0.000165 -0.000284 -0.000331 -4.8e-05 0</velocity>
          <acceleration>0.002843 -0.040903 -0.072796 -0.129532 -0.011728 3.1e-05</acceleration>
          <wrench>1.4e-05 -0.000205 -0.000364 0 -0 0</wrench>
        </link>
        <link name='iris::rotor_3'>
          <pose frame=''>0.854734 -0.197268 0.12781 -0.001826 3.8e-05 -0.005085</pose>
          <velocity>-1e-06 -0.000157 -0.000163 -0.000316 -4.6e-05 0</velocity>
          <acceleration>-4.6e-05 -0.039006 -0.039878 -0.070505 -0.008805 2.3e-05</acceleration>
          <wrench>0 -0.000195 -0.000199 0 -0 0</wrench>
        </link>
        <link name='px4flow::link'>
          <pose frame=''>1.03679 0.000722 0.05444 3.1233 1.56897 -1.59945</pose>
          <velocity>8e-06 -0.000186 -0.000218 -0.000324 -0.000381 -2.7e-05</velocity>
          <acceleration>7.1e-05 -0.001956 0.008874 -0.038614 -0.02303 5.1e-05</acceleration>
          <wrench>4e-06 -9.8e-05 0.000444 0 -0 0</wrench>
        </link>
        <link name='sf10a::link'>
          <pose frame=''>0.986797 0.023422 0.052669 -0.063717 -0.000743 -0.010404</pose>
          <velocity>-6.9e-05 0.080797 0.098649 -0.045419 0.00484 0.002416</velocity>
          <acceleration>0.002528 0.081783 0.976848 -1.03598 0.138171 -0.204555</acceleration>
          <wrench>0.000126 0.004089 0.048842 0 -0 0</wrench>
        </link>
      </model>
      <model name='jersey_barrier'>
        <pose frame=''>-8 -10 0 0 -0 0</pose>
        <scale>1 1 1</scale>
        <link name='link'>
          <pose frame=''>-8 -10 0 0 -0 0</pose>
          <velocity>0 0 0 0 -0 0</velocity>
          <acceleration>0 0 0 0 -0 0</acceleration>
          <wrench>0 0 0 0 -0 0</wrench>
        </link>
      </model>
      <model name='tunnel_tile_5'>
        <pose frame=''>0 0 0 0 -0 1.5708</pose>
        <scale>1 1 1</scale>
        <link name='link'>
          <pose frame=''>0 0 0 0 -0 1.5708</pose>
          <velocity>0 0 0 0 -0 0</velocity>
          <acceleration>0 0 0 0 -0 0</acceleration>
          <wrench>0 0 0 0 -0 0</wrench>
        </link>
      </model>
      <light name='sun'>
        <pose frame=''>0 0 10 0 -0 0</pose>
      </light>
    </state>
  </world>
</sdf>
